<mujoco>
    <compiler angle="radian" assetdir="assets" eulerseq="XYZ" autolimits="true"/>
    <option gravity="0 0 -9.81" timestep="0.002" density="1.225" viscosity="1.48e-5"/>

    <visual>
        <headlight ambient="0.5 0.5 0.5"/>
    </visual>
    
    <asset>
        <material name="grey" rgba="0.4 0.4 0.4 0.5"/>
        <material name="white" rgba="1 1 1 1"/>
        <material name="black" rgba="0 0 0 1"/>
        <material name="green" rgba="0.2 0.8 0.2 0.5"/>

        <mesh name="prop" file="prop.obj" scale="0.001 0.001 0.001"/>
    </asset>
    
    
    <worldbody>
        <light diffuse="0.5 0.5 0.5" pos="0 0 2" dir="0 0 -1"/>
        <geom type="plane" size="1 1 0.1" rgba="0.9 0 0 1"/>

        <body pos="0 0 1" euler="0 0 0">
            <joint type="free"/>
            <inertial pos="0 0 0" mass="2" diaginertia="0.06185585085 0.46467853407 0.47162119244"/>
            <geom type="box" size="0.05 0.05 0.1" material="grey"/>
            <geom type="cylinder" size="0.01 0.1" pos="0 0 0.1" material="white"/>
            <geom type="ellipsoid" size=".13 .13 .01" pos="0 0 0.175" material="green"/>

            <body name="prop1" pos="0 0 0.175" euler="0 0 0">
                <joint name="prop1" type="hinge" axis="0 0 1"/>
                <geom type="mesh" mesh="prop" material="grey"/>
            </body>
            <!-- 
            <body name="prop2" pos="0.195 0.3377 0" euler="-0.34906585 0 1.0472">
                <joint name="prop2" type="hinge" axis="0 0 1"/>
                <geom type="mesh" mesh="prop" material="black"/>
            </body>
            -->
            <site name="actuation"/>
        </body> 
        
    </worldbody>

    <actuator>
        <motor ctrlrange="0 100" gear="0 0 1 0 0 0" site="actuation" name="body_thrust"/>
    </actuator>
</mujoco>