<mujoco model="FTA_drone">
    <compiler angle="radian" assetdir="assets" eulerseq="XYZ" autolimits="true"/>
    <option gravity="0 0 -9.81" timestep="0.002" density="1.225" viscosity="1.48e-5"/>
        
    <asset>
        <material name="grey" rgba="0.2 0.2 0.2 1"/>
        <material name="white" rgba="1 1 1 1"/>
        <material name="black" rgba="0.241 0.90 0.34 1"/>
        <mesh name="base" file="base.obj" scale="0.001 0.001 0.001"/>
        <mesh name="prop" file="prop.obj" scale="0.001 0.001 0.001"/>
    </asset>
    
    
    <worldbody>
        <body pos="0 0 1" euler="0 0 0">
            <joint type="free"/>
            <inertial pos="0 0 0" mass="2" diaginertia="0.06185585085 0.46467853407 0.47162119244"/>
            <geom type="mesh" mesh="base" material="grey"/>
            <geom type="cylinder" size="0.01 0.3475" pos="0.300943827 -0.17375 0.0" euler="-2.61799 1.5708 0" material = "white"/>
            <body name="prop1" pos="0.38998 0 0" euler="0.34906585 0 0">
                <joint name="prop1" type="hinge" axis="0 0 1"/>
                <geom type="mesh" mesh="prop" material="black"/>
            </body>
            <body name="prop2" pos="0.195 0.3377 0" euler="-0.34906585 0 1.0472">
                <joint name="prop2" type="hinge" axis="0 0 1"/>
                <geom type="mesh" mesh="prop" material="black"/>
            </body>
            <body name="prop3" pos="-0.195 0.3377 0" euler="0.34906585 0 2.0944">
                <joint name="prop3" type="hinge" axis="0 0 1"/>
                <geom type="mesh" mesh="prop" material="black"/>
            </body>
            <body name="prop4" pos="-0.38998 0 0" euler="0.34906585 0 0">
                <joint name="prop4" type="hinge" axis="0 0 1"/>
                <geom type="mesh" mesh="prop" material="black"/>
            </body>
            <body name="prop5" pos="-0.195 -0.3377 0" euler="-0.34906585 0 1.0472">
                <joint name="prop5" type="hinge" axis="0 0 1"/>
                <geom type="mesh" mesh="prop" material="black"/>
            </body>
            <body name="prop6" pos="0.195 -0.3377 0" euler="0.34906585 0 2.0944">
                <joint name="prop6" type="hinge" axis="0 0 1"/>
                <geom type="mesh" mesh="prop" material="black"/>
            </body>
        </body> 
    </worldbody>




</mujoco>